<?xml version="1.0" ?>
<robot name="testbed_bullet">

<material name="silver">
  <color rgba="0.700 0.700 0.700 1.000"/>
</material>

<link name="base_link">
  <inertial>
    <origin xyz="-7.860260228302348e-18 0.02 0.14485022185990865" rpy="0 0 0"/>
    <mass value="9.083075116533994"/>
    <inertia ixx="0.06509661469140615" iyy="0.07119787662370206" izz="0.008523415296704955" ixy="-3.851859888774472e-34" iyz="0.0" ixz="-1.0341629982579278e-17"/>
  </inertial>
  <visual>
    <origin xyz="0 0 0" rpy="0 0 0"/>
    <geometry>
      <mesh filename="meshes/base_link.stl" scale="0.001 0.001 0.001"/>
    </geometry>
    <material name="silver"/>
    <material/>
  </visual>
  <collision>
    <origin xyz="0 0 0" rpy="0 0 0"/>
    <geometry>
      <mesh filename="meshes/base_link.stl" scale="0.001 0.001 0.001"/>
    </geometry>
  </collision>
</link>

<link name="joint1">
  <inertial>
    <origin xyz="0.0 -0.012499999999999997 0.0" rpy="0 0 0"/>
    <mass value="0.9864600932271947"/>
    <inertia ixx="0.0004459621671464506" iyy="0.0007891680745817434" izz="0.00044596216714646783" ixy="3.552713678800501e-19" iyz="0.0" ixz="-6.247091732802801e-19"/>
  </inertial>
  <visual>
    <origin xyz="-0.0 -0.0 -0.25" rpy="0 0 0"/>
    <geometry>
      <mesh filename="meshes/joint1.stl" scale="0.001 0.001 0.001"/>
    </geometry>
    <material name="silver"/>
    <material/>
  </visual>
  <collision>
    <origin xyz="-0.0 -0.0 -0.25" rpy="0 0 0"/>
    <geometry>
      <mesh filename="meshes/joint1.stl" scale="0.001 0.001 0.001"/>
    </geometry>
  </collision>
</link>

<link name="link21">
  <inertial>
    <origin xyz="-0.06427288587805237 -0.0049999999999999975 0.0" rpy="0 0 0"/>
    <mass value="0.9228171105920571"/>
    <inertia ixx="0.0002841549874320129" iyy="0.0032272298811555633" izz="0.0029584551789000792" ixy="-2.168404344971009e-19" iyz="8.673617379884035e-19" ixz="-3.469446951953614e-18"/>
  </inertial>
  <visual>
    <origin xyz="-0.0 0.025 -0.25" rpy="0 0 0"/>
    <geometry>
      <mesh filename="meshes/link21.stl" scale="0.001 0.001 0.001"/>
    </geometry>
    <material name="silver"/>
    <material/>
  </visual>
  <collision>
    <origin xyz="-0.0 0.025 -0.25" rpy="0 0 0"/>
    <geometry>
      <mesh filename="meshes/link21.stl" scale="0.001 0.001 0.001"/>
    </geometry>
  </collision>
</link>

<joint name="Revolute_1" type="continuous">
  <origin xyz="0.0 0.0 0.25" rpy="0 0 0"/>
  <parent link="base_link"/>
  <child link="joint1"/>
  <axis xyz="0.0 1.0 0.0"/>
  <!-- <dynamics damping="0.5" friction="0.5"/> Add this line for friction and damping -->
</joint>
<transmission name="Revolute_1_tran">
  <type>transmission_interface/SimpleTransmission</type>
  <joint name="Revolute_1">
    <hardwareInterface>PositionJointInterface</hardwareInterface>
  </joint>
  <actuator name="Revolute_1_actr">
    <hardwareInterface>PositionJointInterface</hardwareInterface>
    <mechanicalReduction>1</mechanicalReduction>
  </actuator>
</transmission>

<joint name="Rigid_2" type="fixed">
  <origin xyz="0.0 -0.025 0.0" rpy="0 0 0"/>
  <parent link="joint1"/>
  <child link="link21"/>
</joint>

</robot>
